<robot name="flapper">
  <link name="torso">
    <inertial>
      <origin xyz="-3.39095744681197E-06               1.3039607029558E-08               -0.00023956863202956" rpy="0 0 0" />
      <mass value="0.00798" />
      <inertia ixx="6.65E-07" ixy="0.0001E-9" ixz="0.0001E-9" iyy="1.022E-06" iyz="0.0001E-9" izz="4.26E-07" />
    </inertial>
    <visual>
      <origin xyz="0 0 0" rpy="0 0 0" />
      <geometry>
        <mesh filename="./meshes/torso.STL" />
      </geometry>
      <material name="">
        <color rgba="0.792156862745098 0.819607843137255 0.933333333333333 1" />
      </material>
    </visual>
    <collision>
      <origin xyz="0 0 0" rpy="0 0 0" />
      <geometry>
        <mesh filename="./meshes/torso.STL" />
      </geometry>
    </collision>
  </link>
  <link name="left_wing_rod">
    <inertial>
      <origin xyz="0 0 0" rpy="0 0 0" />
      <mass value="0.0006062112259638999" />
      <inertia ixx="5.842142941965028e-08" ixy="0.0001E-9" ixz="-3.957474088691156e-08" iyy="6.352914352608075e-07" iyz="0.0001E-9" izz="6.046694805744028e-07" />
    </inertial>
    <visual>
      <origin xyz="0 0 0" rpy="0 0 0" />
      <geometry>
        <mesh filename="./meshes/left_wing_rod.STL" />
      </geometry>
      <material name="">
        <color rgba="0.792156862745098 0.819607843137255 0.933333333333333 1" />
      </material>
    </visual>
    <collision>
      <origin xyz="0 0 0" rpy="0 0 0" />
      <geometry>
        <mesh filename="./meshes/left_wing_rod.STL" />
      </geometry>
    </collision>
  </link>
  <joint name="left_Stroke_joint" type="continuous">
    <origin xyz="0.016247 0 0.0095033" rpy="0 0 0" />
    <parent link="torso" />
    <child link="left_wing_rod" />
    <axis xyz="0 0 1" />
  </joint>
  <link name="left_wing">
    <inertial>
      <origin xyz="0 0 0" rpy="0 0 0" />
      <mass value="7.518147568062195e-06" />
      <inertia ixx="1.8326857921943397e-10" ixy="0.0001E-9" ixz="-1.729645253614785e-09" iyy="3.310837765071537e-08" iyz="0.0001E-9" izz="3.292553941714803e-08" />
    </inertial>
    <visual>
      <origin xyz="0 0 0" rpy="0 0 0" />
      <geometry>
        <mesh filename="./meshes/left_wing.STL" />
      </geometry>
      <material name="">
        <color rgba="0.792156862745098 0.819607843137255 0.933333333333333 1" />
      </material>
    </visual>
    <collision>
      <origin xyz="0 0 0" rpy="0 0 0" />
      <geometry>
        <mesh filename="./meshes/left_wing.STL" />
      </geometry>
    </collision>
  </link>
  <joint name="left_rotate_joint" type="continuous">
    <origin xyz="0 0 -0.0057" rpy="0 0 0" />
    <parent link="left_wing_rod" />
    <child link="left_wing" />
    <axis xyz="1 0 0" />
  </joint>
  <link name="right_wing_rod">
    <inertial>
      <origin xyz="0 0 0" rpy="0 0 0" />
      <mass value="0.0006062112259638999" />
      <inertia ixx="5.842142941965028e-08" ixy="0.0001E-9" ixz="3.957474088691156e-08" iyy="6.352914352608075e-07" iyz="0.0001E-9" izz="6.046694805744028e-07" />
    </inertial>
    <visual>
      <origin xyz="0 0 0" rpy="0 0 0" />
      <geometry>
        <mesh filename="./meshes/right_wing_rod.STL" />
      </geometry>
      <material name="">
        <color rgba="0.792156862745098 0.819607843137255 0.933333333333333 1" />
      </material>
    </visual>
    <collision>
      <origin xyz="0 0 0" rpy="0 0 0" />
      <geometry>
        <mesh filename="./meshes/right_wing_rod.STL" />
      </geometry>
    </collision>
  </link>
  <joint name="right_stroke_joint" type="continuous">
    <origin xyz="-0.016253 0 0.0095033" rpy="0 0 0" />
    <parent link="torso" />
    <child link="right_wing_rod" />
    <axis xyz="0 0 1" />
  </joint>
  <link name="right_wing">
    <inertial>
      <origin xyz="0 0 0" rpy="0 0 0" />
      <mass value="7.518147568062195e-06" />
      <inertia ixx="1.8326857921943397e-10" ixy="0.0001E-9" ixz="1.729645253614785e-09" iyy="3.310837765071537e-08" iyz="0.0001E-9" izz="3.292553941714803e-08" />
    </inertial>
    <visual>
      <origin xyz="0 0 0" rpy="0 0 0" />
      <geometry>
        <mesh filename="./meshes/right_wing.STL" />
      </geometry>
      <material name="">
        <color rgba="0.792156862745098 0.819607843137255 0.933333333333333 1" />
      </material>
    </visual>
    <collision>
      <origin xyz="0 0 0" rpy="0 0 0" />
      <geometry>
        <mesh filename="./meshes/right_wing.STL" />
      </geometry>
    </collision>
  </link>
  <joint name="right_rotate_joint" type="continuous">
    <origin xyz="0 0 -0.0057" rpy="0 0 0" />
    <parent link="right_wing_rod" />
    <child link="right_wing" />
    <axis xyz="-1 0 0" />
  </joint>
</robot>